Workbook

Sheet BALANCE SHEET
A1: ASSETS | B1: 2025 | C1: 2024 | D1: 2023
A2: Non-current assets
A4: Property, plant and equipment | B4: 8625 | C4: 8031 | D4: 6949
A5: Capital work-in-progres | B5: 1009 | C5: 1025 | D5: 1132
A6: Goodwill | B6: 17466 | C6: 17466 | D6: 17316
A7: Goodwill on consolidation | D7: 150
A8: Other intangible assets | B8: 28244 | C8: 28247 | D8: 28263
A9: Investments accounted for using the equity method | B9: 57 | C9: 65 | D9: 69
A10: Financial assets
A11: Investments | B11: 2 | C11: 2 | D11: 2
A12: Loans | B12: 87 | C12: 102 | D12: 98
A13: Other financial assets | B13: 763 | C13: 760 | D13: 725
A14: Deferred tax assets | B14: 17 | C14: 10 | D14: 10
A15: Non-current tax assets (net) | B15: 1199 | C15: 1175 | D15: 1164
A16: Other non-current assets | B16: 360 | C16: 292 | D16: 211
A17: Total – Non-current assets (A) | B17: =SUM(B4:B16) -> 57829 | C17: =SUM(C4:C16) -> 57175 | D17: =SUM(D4:D16) -> 56089
A18: Current assets
A19: Inventories | B19: 4415 | C19: 4022 | D19: 4251
A20: Financial assets
A21: Investment | B21: 3751 | C21: 4558 | D21: 2811
A22: Trade receivables | B22: 3819 | C22: 2997 | D22: 3079
A23: Cash and cash equivalents | B23: 6071 | C23: 825 | D23: 714
A24: Bank balances other than cash and cash equivalents mentioned above | B24: 1483 | C24: 6734 | D24: 3964
A25: Loans | B25: 46 | C25: 38 | D25: 36
A26: Other financial assets | B26: 1488 | C26: 1425 | D26: 1386
A27: Other current assets | B27: 955 | C27: 713 | D27: 745
A28: Assets held for sale | B28: 23 | C28: 12 | D28: 12
A29: Total – Current assets (B) | B29: =SUM(B19:B28) -> 22051 | C29: =SUM(C19:C28) -> 21324 | D29: =SUM(D19:D28) -> 16998
A30: TOTAL ASSETS (A+B) | B30: =SUM(B29,B17) -> 79880 | C30: =SUM(C29,C17) -> 78499 | D30: =SUM(D29,D17) -> 73087
A32: EQUITY AND LIABILITIES
A33: Equity
A34: Equity share capital | B34: 235 | C34: 235 | D34: 235
A35: Other equity | B35: 49167 | C35: 50983 | D35: 50069
A36: Non-controlling interests | B36: 207 | C36: 205 | D36: 218
A37: Total - Equity (A) | B37: =SUM(B34:B36) -> 49609 | C37: =SUM(C34:C36) -> 51423 | D37: =SUM(D34:D36) -> 50522
A38: Liabilities
A39: Non-current liabilities
A40: Financial liabilities
A41: Lease Liabilities | B41: 1243 | C41: 1106 | D41: 807
A42: other financial liabilities | B42: 680 | C42: 715 | D42: 860
...

Sheet CASH FLOW
B1: 2025 | C1: 2024 | D1: 2023
A2: CASH FLOWS FROM OPERATING ACTIVITIES
A3: Profit before tax from continuing operations and before share of equity accounted investee | B3: 14415 | C3: 13926 | D3: 13345
A4: Adjustments for:
A5: Depreciation and amortisation expenses | B5: 1363 | C5: 1216 | D5: 1152
A6: Profit/loss on sale of property, plant and equipment | B6: 43 | C6: 18 | D6: -100
A7: Contingent consideration true up for business combination | D7: -2
A8: fair value gain on financial liability on acquisition | B8: 120 | C8: -132
A9: Finance Income | B9: -755 | C9: -546 | D9: -411
A10: Dividend income | C10: -3 | D10: -2
A11: Other non operating income – Fair value gain on investments | B11: -256 | C11: -249 | D11: -99
A12: Interest expense | B12: 372 | C12: 317 | D12: 114
A13: Movement in provision toward litigation | B13: -595 | C13: -159
A14: Provision for expenses on employee stock options | D14: 1
A15: Profit on sale of brand rights | D15: -60
A16: Payment from Retirement Benefit Scheme Reserve | B16: -1 | C16: -1 | D16: -1
A17: share losses on joint venture | B17: 8 | C17: 4 | D17: 1
A18: Transaction cost from acquisition | D18: 2
A19: Inventory written off net of Provision/(write back) for Inventory | B19: 189 | C19: 167 | D19: 184
A20: Bad debts/assets written off net of Provision/(write back) | B20: 24 | C20: -11 | D20: -27
A21: Mark-to-market (gain)/ loss on derivative financial instruments | B21: 4 | C21: -10 | D21: -8
A22: share based expences | B22: 11
A23: Cash Generated from operations before working capital changes | B23: =SUM(B3:B22) -> 14942 | C23: =SUM(C3:C21) -> 14537 | D23: =SUM(D3:D21) -> 14089
A24: Adjustments for:
A25: (Increase)/decrease in Non-Current Assets | B25: -87 | C25: -30 | D25: -14
A26: (Increase)/decrease in Current Assets | B26: -1275 | C26: 220 | D26: -1111
A27: (Increase)/decrease in Inventories | B27: -584 | C27: 74 | D27: -339
A28: Increase/(decrease) in Non-Current Liabilities | B28: -284 | C28: 128 | D28: -116
A29: Increase/(decrease) in Current Liabilities | B29: 1442 | C29: 921 | D29: 622
A30: Cash flows generated from operations | B30: =SUM(B23:B29) -> 14154 | C30: =SUM(C23:C29) -> 15850 | D30: =SUM(D23:D29) -> 13131
A31: Taxes paid (net of refunds) | B31: -2268 | C31: -381 | D31: -3138
A32: Profit/(Loss) from Joint venture | D32: -1
A33: Profit/(Loss) from discontinued operations | D33: -1
A35: Net cash flows generated from operating activities - [A] | B35: =SUM(B30:B33) -> 11886 | C35: =SUM(C30:C33) -> 15469 | D35: =SUM(D30:D33) -> 9991
A36: CASH FLOWS FROM INVESTING ACTIVITIES:
A37: Purchase of property, plant and equipment | B37: -1254 | C37: -1468 | D37: -1174
A38: Sale proceeds of property, plant and equipment | B38: 13 | C38: 20 | D38: 121
A39: Purchase of intangible assets | B39: -21 | C39: -9 | D39: -18
A40: Sale proceeds of intangible assets (brand rights) | B40: 595 | D40: 60
A41: Investment in subsidiary | D41: -264
...

Sheet INCOME STATEMENT
B1: 2025 | C1: 2024 | D1: 2023
A2: INCOME
A3: Revenue from operations | B3: 63121 | C3: 61896 | D3: 60580
A4: Other income | B4: 1017 | C4: 811 | D4: 512
A5: TOTAL INCOME | B5: =SUM(B3:B4) -> 64138 | C5: =SUM(C3:C4) -> 62707 | D5: =SUM(D3:D4) -> 61092
A6: EXPENSES
A7: Cost of materials consumed | B7: 19458 | C7: 19257 | D7: 20212
A8: Purchases of stock-in-trade | B8: 11273 | C8: 10514 | D8: 11579
A9: Changes in inventories of finished goods, Stock-in-Trade and work-in-progress | B9: -153 | C9: -11 | D9: -75
A10: Employee benefits expense | B10: 3077 | C10: 3009 | D10: 2854
A11: Finance costs | B11: 395 | C11: 334 | D11: 114
A12: Depreciation and amortisation expense | B12: 1355 | C12: 1216 | D12: 1137
A13: Other expenses | B13: 14615 | C13: 14464 | D13: 11861
A14: TOTAL EXPENSES | B14: =SUM(B7:B13) -> 50020 | C14: =SUM(C7:C13) -> 48783 | D14: =SUM(D7:D13) -> 47682
A15: Profit before Exceptional Items and tax and before share of equity accounted investee | B15: 14118 | C15: 13924 | D15: 13410
A16: Share of loss of equity accounted investee net of tax | B16: -8 | C16: -4 | D16: -1
A17: Profit before exceptional items and tax | B17: =SUM(B15:B16) -> 14110 | C17: =SUM(C15:C16) -> 13920 | D17: =SUM(D15:D16) -> 13409
A18: Exceptional items (net) | B18: 305 | C18: 6 | D18: -64
A19: Profit before tax from Continuing Operations | B19: =SUM(B17:B18) -> 14415 | C19: =SUM(C17:C18) -> 13926 | D19: =SUM(D17:D18) -> 13345
A20: Tax expenses
A21: Current tax | B21: -3620 | C21: -3521 | D21: -3001
A22: Deferred tax charge | B22: -124 | C22: -123 | D22: -200
A23: Profit after tax from Continuing Operations (A) | B23: =SUM(B19:B22) -> 10671 | C23: =SUM(C19:C22) -> 10282 | D23: =SUM(D19:D22) -> 10144
A24: Profit/(Loss) from discontinued operations before tax | D24: -1
A25: Tax adjustment of discontinued operations
A26: Profit/(Loss) from discontinued operations after tax (B) | D26: =SUM(D24:D25) -> -1
A27: PROFIT FOR THE YEAR (A+B) | B27: =SUM(B26,B23) -> 10671 | C27: =SUM(C26,C23) -> 10282 | D27: =SUM(D26,D23) -> 10143
A28: OTHER COMPREHENSIVE INCOME
A29: Items that will not be reclassified subsequently to profit or loss
A30: Remeasurements of the net defined benefit plans | B30: -22 | C30: 36 | D30: -17
A31: Income tax relating to items that will not be reclassified subsequently to profit or loss
A32: Remeasurements of the net defined benefit plans | B32: 5 | C32: -9 | D32: 4
A33: Items that will be reclassified subsequently to profit or loss
A34: Fair value of debt instruments through other comprehensive income | C34: 2 | D34: -1
A35: Fair value of cash flow hedges through other comprehensive income | D35: -21
A36: Income tax relating to items that will be reclassified subsequently to profit or loss
A37: Fair value of debt instruments through other comprehensive income | C37: 0 | D37: 0
A38: Fair value of cash flow hedges through other comprehensive income | B38: -2 | C38: -1 | D38: 9
A39: Tax on above | C39: -3
A40: OTHER COMPREHENSIVE INCOME FOR THE YEAR (C) | B40: =SUM(B30:B39) -> -19 | C40: =SUM(C30:C39) -> 25 | D40: =SUM(D30:D38) -> -26
...

Sheet RATIOS
A1: RATIOS CALCULATION | C1: 2025 | D1: 2024 | E1: 2023
A2: LIQUIDITY RATIOS | G2: DuPont Analysis Calculation
A3: Current | B3: Current Assets/Current liability | C3: =('INCOME STATEMENT'!B3-('INCOME STATEMENT'!B7+'INCOME STATEMENT'!B8+'INCOME STATEMENT'!B9))/'INCOME STATEMENT'!B3 -> 0.51556534 | D3: =('INCOME STATEMENT'!C3-('INCOME STATEMENT'!C7+'INCOME STATEMENT'!C8+'INCOME STATEMENT'!C9))/'INCOME STATEMENT'!C3 -> 0.51919349 | E3: =('INCOME STATEMENT'!D3-('INCOME STATEMENT'!D7+'INCOME STATEMENT'!D8+'INCOME STATEMENT'!D9))/'INCOME STATEMENT'!D3 -> 0.47646088 | G3: ROE | H3: Net Profit Margin × Asset Turnover × Equity Multiplier
A4: Quick | B4: (Current Assets-Inventory)/Current liability | C4: =('BALANCE SHEET'!B29-'BALANCE SHEET'!B19)/'BALANCE SHEET'!B58 -> 1.066457 | D4: =('BALANCE SHEET'!C29-'BALANCE SHEET'!C19)/'BALANCE SHEET'!C58 -> 1.3434273 | E4: =('BALANCE SHEET'!D29-'BALANCE SHEET'!D19)/'BALANCE SHEET'!D58 -> 1.0597772 | G4: ROE | H4: =('INCOME STATEMENT'!B27/'INCOME STATEMENT'!B3)*('INCOME STATEMENT'!B3/AVERAGE('BALANCE SHEET'!B30,'BALANCE SHEET'!C30))*(AVERAGE('BALANCE SHEET'!B30,'BALANCE SHEET'!C30)/AVERAGE('BALANCE SHEET'!B37,'BALANCE SHEET'!C37)) -> 0.21124
A5: SOLVENCY RATIOS
A6: Debt to Asset | B6: Total Debt / Total Assets | C6: =('BALANCE SHEET'!B46+'BALANCE SHEET'!B58)/'BALANCE SHEET'!B30 -> 0.37895593 | D6: =('BALANCE SHEET'!C46+'BALANCE SHEET'!C58)/'BALANCE SHEET'!C30 -> 0.34492159 | E6: =('BALANCE SHEET'!D46+'BALANCE SHEET'!D58)/'BALANCE SHEET'!D30 -> 0.30874164
A7: Debt to Equity | B7: Total liability/Shareholders Equity | C7: =('BALANCE SHEET'!B46+'BALANCE SHEET'!B58)/'BALANCE SHEET'!B37 -> 0.6101917 | D7: =('BALANCE SHEET'!C46+'BALANCE SHEET'!C58)/'BALANCE SHEET'!C37 -> 0.52653482 | E7: =('BALANCE SHEET'!D46+'BALANCE SHEET'!D58)/'BALANCE SHEET'!D37 -> 0.44663711
A8: PROFITABILITY RATIOS
A9: Gross profit margin | B9: (Revenue - Cost of Goods Sold) / Revenue | C9: =('INCOME STATEMENT'!B3-('INCOME STATEMENT'!B7+'INCOME STATEMENT'!B8+'INCOME STATEMENT'!B9))/'INCOME STATEMENT'!B3 -> 0.51556534 | D9: =('INCOME STATEMENT'!C3-('INCOME STATEMENT'!C7+'INCOME STATEMENT'!C8+'INCOME STATEMENT'!C9))/'INCOME STATEMENT'!C3 -> 0.51919349 | E9: =('INCOME STATEMENT'!D3-('INCOME STATEMENT'!D7+'INCOME STATEMENT'!D8+'INCOME STATEMENT'!D9))/'INCOME STATEMENT'!D3 -> 0.47646088
A10: Net profit margin | B10: Net Income / Revenue | C10: ='INCOME STATEMENT'!B27/'INCOME STATEMENT'!B3 -> 0.16905626 | D10: ='INCOME STATEMENT'!C27/'INCOME STATEMENT'!C3 -> 0.16611736 | E10: ='INCOME STATEMENT'!D27/'INCOME STATEMENT'!D3 -> 0.1674315
A11: Operating profit margin | B11: EBIT / Interest Expense | C11: =('INCOME STATEMENT'!B19+'INCOME STATEMENT'!B11)/'INCOME STATEMENT'!B3 -> 0.23462873 | D11: =('INCOME STATEMENT'!C19+'INCOME STATEMENT'!C11)/'INCOME STATEMENT'!C3 -> 0.23038645 | E11: =('INCOME STATEMENT'!D19+'INCOME STATEMENT'!D11)/'INCOME STATEMENT'!D3 -> 0.22216903
A12: Return on Equity(ROE) | B12: Net Income / Average Shareholder Equity | C12: ='INCOME STATEMENT'!B27/AVERAGE('BALANCE SHEET'!B37,'BALANCE SHEET'!C37) -> 0.21124 | D12: ='INCOME STATEMENT'!C27/AVERAGE('BALANCE SHEET'!C37,'BALANCE SHEET'!D37) -> 0.20171661 | E12: ='INCOME STATEMENT'!D27/AVERAGE('BALANCE SHEET'!D37,'BALANCE SHEET'!E37) -> 0.20076402
A13: Return on assets(ROA) | B13: Net Income / Average Total Assets | C13: ='INCOME STATEMENT'!B27/AVERAGE('BALANCE SHEET'!B30,'BALANCE SHEET'!C30) -> 0.13475271 | D13: ='INCOME STATEMENT'!C27/AVERAGE('BALANCE SHEET'!C30,'BALANCE SHEET'!D30) -> 0.13565897 | E13: ='INCOME STATEMENT'!D27/AVERAGE('BALANCE SHEET'!D30,'BALANCE SHEET'!E30) -> 0.13877981
A14: EFFICIENCY RATIOS
A15: Inventory Turnover | B15: Cost of Goods Sold / Average Inventory | C15: =('INCOME STATEMENT'!B7+'INCOME STATEMENT'!B8+'INCOME STATEMENT'!B9)/AVERAGE('BALANCE SHEET'!B19,'BALANCE SHEET'!C19) -> 7.2485481 | D15: =('INCOME STATEMENT'!C7+'INCOME STATEMENT'!C8+'INCOME STATEMENT'!C9)/AVERAGE('BALANCE SHEET'!C19,'BALANCE SHEET'!D19) -> 7.1944881 | E15: =('INCOME STATEMENT'!D7+'INCOME STATEMENT'!D8+'INCOME STATEMENT'!D9)/AVERAGE('BALANCE SHEET'!D19,'BALANCE SHEET'!E19) -> 7.4608327
A16: Accounts Receivable | B16: Revenue / Average Accounts Receivable | C16: ='INCOME STATEMENT'!B3/AVERAGE('BALANCE SHEET'!B22,'BALANCE SHEET'!C22) -> 18.52142 | D16: ='INCOME STATEMENT'!C3/AVERAGE('BALANCE SHEET'!C22,'BALANCE SHEET'!D22) -> 20.37393 | E16: ='INCOME STATEMENT'!D3/AVERAGE('BALANCE SHEET'!D22,'BALANCE SHEET'!E22) -> 19.675219
A17: Asset Turnover | B17: Revenue / Average Total Assets | C17: ='INCOME STATEMENT'!B3/AVERAGE('BALANCE SHEET'!B30,'BALANCE SHEET'!C30) -> 0.797088 | D17: ='INCOME STATEMENT'!C3/AVERAGE('BALANCE SHEET'!C30,'BALANCE SHEET'!D30) -> 0.81664534 | E17: ='INCOME STATEMENT'!D3/AVERAGE('BALANCE SHEET'!D30,'BALANCE SHEET'!E30) -> 0.82887518
A18: MARKET VALUE RATIOS
A19: Earnings Per Share (EPS) | B19: (Net Income - Preferred Dividends) / Weighted Average Shares Outstanding | C19: ='INCOME STATEMENT'!B27/C24 -> 45.416241 | D19: ='INCOME STATEMENT'!C27/D24 -> 43.76064 | E19: ='INCOME STATEMENT'!D27/E24 -> 43.16905
A20: Price-to-Earnings (P/E) Ratio | B20: Market Price Per Share / Earnings Per Share | C20: =C25/C19 -> 52.095901 | D20: =D25/D19 -> 50.776223 | E20: =E25/E19 -> 58.259332
A21: Book Value Per Share | B21: Shareholder Equity / Shares Outstanding | C21: ='BALANCE SHEET'!B37/C24 -> 211.13807 | D21: ='BALANCE SHEET'!C37/D24 -> 218.85853 | E21: ='BALANCE SHEET'!D37/E24 -> 215.02383
A24: Shares Outstanding (cr) | C24: 234.96 | D24: 234.96 | E24: 234.96
A25: Market Closing Price (End of the year) | C25: 2366 | D25: 2222 | E25: 2515
